Workbook
Name BoxPlot: "BoxPlot"
Name Bubble: "Bubble"
Name Candlestick: "Candlestick"
Name Chart: "Chart"
Name ChartImage: "ChartImage"
Name ColumnRange: "ColumnRange"
Name Dumbbell: "Dumbbell"
Name Heatmap: "Heatmap"
Name Histogram: "Histogram"
Name Map: "Map"
Name OHLC: "OHLC"
Name PieChart: "PieChart"
Name Scatter: "Scatter"
Name Series: "Series"
Name Stripe: "Stripe"
Name Table: "Table"
Name TreeMap: "TreeMap"
Name Waterfall: "Waterfall"

Sheet before_after
A1: name | B1: public_rating | C1: model_rating_oct | D1: model_rating_dec | E1: model delta (rating notches, -ve = worse, +ve = better) | F1: Adjustment | G1: LS_rating | H1: LS_letter | I1: Analyst | J1: Gov_Factor 2023_old | K1: Gov_Factor_2023_new | L1: Gov_Factor_2024 | M1: Method Change | N1: Time Change | O1: Total Change | P1: Rating impact (x2.8) | Q1: Comments
A2: United States | B2: 21 | C2: 18.856549 | D2: 18.705977 | E2: =D2-C2 -> -0.15057239 | F2: 0 | G2: 18.705977 | H2: AA- | I2: BRIAN HORRIGAN | J2: 0.90987171 | K2: 0.83764433 | L2: 0.82855756 | M2: =K2-J2 -> -0.072227379 | N2: =L2-K2 -> -0.009086772 | O2: =M2+N2 -> -0.081314151 | P2: =O2*2.804471 -> -0.22804318
A3: United Kingdom | B3: 19.333333 | C3: 19.33286 | D3: 19.153396 | E3: =D3-C3 -> -0.1794638 | F3: 0 | G3: 19.153396 | H3: AA- | I3: JON LEVY | J3: 1.1678865 | K3: 1.1126805 | L3: 1.0991731 | M3: =K3-J3 -> -0.055206058 | N3: =L3-K3 -> -0.013507412 | O3: =M3+N3 -> -0.06871347 | P3: =O3*2.804471 -> -0.19270493
A4: Austria | B4: 20.666667 | C4: 18.750964 | D4: 18.723972 | E4: =D4-C4 -> -0.026991694 | F4: 0 | G4: 18.723972 | H4: AA- | I4: Not covered | J4: 1.2393602 | K4: 1.3053375 | L4: 1.2334629 | M4: =K4-J4 -> 0.065977335 | N4: =L4-K4 -> -0.071874579 | O4: =M4+N4 -> -0.0058972436 | P4: =O4*2.804471 -> -0.016538649
A5: Belgium | B5: 19 | C5: 17.424721 | D5: 17.541837 | E5: =D5-C5 -> 0.11711549 | F5: 0 | G5: 17.541837 | H5: A+ | I5: Not covered | J5: 1.0218825 | K5: 1.0734132 | L5: 1.0532288 | M5: =K5-J5 -> 0.051530707 | N5: =L5-K5 -> -0.020184446 | O5: =M5+N5 -> 0.031346261 | P5: =O5*2.804471 -> 0.087909679
A6: Denmark | B6: 22 | C6: 23.325837 | D6: 23.251883 | E6: =D6-C6 -> -0.07395359 | F6: 0 | G6: 22 | H6: AAA | I6: Not covered | J6: 1.7698904 | K6: 1.8503604 | L6: 1.7928139 | M6: =K6-J6 -> 0.080469966 | N6: =L6-K6 -> -0.057546497 | O6: =M6+N6 -> 0.022923469 | P6: =O6*2.804471 -> 0.064288203
A7: France | B7: 18.666667 | C7: 18.393059 | D7: 17.913243 | E7: =D7-C7 -> -0.47981588 | F7: 0.2 | G7: 18.113243 | H7: A+ | I7: JON LEVY | J7: 0.94904984 | K7: 0.90804671 | L7: 0.80220623 | M7: =K7-J7 -> -0.041003129 | N7: =L7-K7 -> -0.10584047 | O7: =M7+N7 -> -0.1468436 | P7: =O7*2.804471 -> -0.41181863
A8: Germany | B8: 22 | C8: 21.285506 | D8: 21.331576 | E8: =D8-C8 -> 0.046069524 | F8: 0.4 | G8: 21.731576 | H8: AAA | I8: JON LEVY | J8: 1.2672908 | K8: 1.3550906 | L8: 1.3012734 | M8: =K8-J8 -> 0.087799731 | N8: =L8-K8 -> -0.053817119 | O8: =M8+N8 -> 0.033982612 | P8: =O8*2.804471 -> 0.09530325
A9: Italy | B9: 14.333333 | C9: 16.48874 | D9: 16.575605 | E9: =D9-C9 -> 0.086865333 | F9: 0 | G9: 16.575605 | H9: A | I9: JON LEVY | J9: 0.54432528 | K9: 0.6127735 | L9: 0.54514429 | M9: =K9-J9 -> 0.068448226 | N9: =L9-K9 -> -0.067629215 | O9: =M9+N9 -> 0.00081901122 | P9: =O9*2.804471 -> 0.0022968932
A10: Luxembourg | B10: 22 | C10: 21.03868 | D10: 21.06722 | E10: =D10-C10 -> 0.028539926 | F10: 0 | G10: 21.06722 | H10: AA+ | I10: Not covered | J10: 1.6981916 | K10: 1.7308632 | L10: 1.7286095 | M10: =K10-J10 -> 0.032671661 | N10: =L10-K10 -> -0.0022537421 | O10: =M10+N10 -> 0.030417919 | P10: =O10*2.804471 -> 0.085306171
A11: Netherlands | B11: 22 | C11: 21.516545 | D11: 21.4562 | E11: =D11-C11 -> -0.060344247 | F11: 0 | G11: 21.4562 | H11: AA+ | I11: Not covered | J11: 1.4952929 | K11: 1.5334098 | L11: 1.4922354 | M11: =K11-J11 -> 0.038116857 | N11: =L11-K11 -> -0.041174408 | O11: =M11+N11 -> -0.0030575512 | P11: =O11*2.804471 -> -0.0085748136
A12: Norway | B12: 22 | C12: 23.834111 | D12: 23.741085 | E12: =D12-C12 -> -0.093025612 | F12: 0 | G12: 22 | H12: AAA | I12: JINGZHOU MENG | J12: 1.6551482 | K12: 1.7129826 | L12: 1.6972911 | M12: =K12-J12 -> 0.057834394 | N12: =L12-K12 -> -0.015691464 | O12: =M12+N12 -> 0.042142931 | P12: =O12*2.804471 -> 0.11818863
A13: Sweden | B13: 22 | C13: 21.825526 | D13: 21.812877 | E13: =D13-C13 -> -0.012648835 | F13: 0 | G13: 21.812877 | H13: AAA | I13: JINGZHOU MENG | J13: 1.5208156 | K13: 1.5655746 | L13: 1.5488989 | M13: =K13-J13 -> 0.044759028 | N13: =L13-K13 -> -0.016675688 | O13: =M13+N13 -> 0.02808334 | P13: =O13*2.804471 -> 0.078758913
... A23: Spain | B23: 17 | C23: 17.592002 | D23: 17.65874 | E23: =D23-C23 -> 0.066738639 | F23: 0 | G23: 17.65874 | H23: A+ | I23: JINGZHOU MENG | J23: 0.62668272 | K23: 0.68075657 | L23: 0.6376626 | M23: =K23-J23 -> 0.05407385 | N23: =L23-K23 -> -0.04309397 | O23: =M23+N23 -> 0.01097988 | P23: =O23*2.804471 -> 0.030792755
A24: Turkey | B24: 10 | C24: 12.005381 | D24: 11.604822 | E24: =D24-C24 -> -0.40055898 | F24: -0.5 | G24: 11.104822 | H24: BB | I24: HASSAN MALIK | J24: -0.80655186 | K24: -0.84427835 | L24: -0.88491213 | M24: =K24-J24 -> -0.037726488 | N24: =L24-K24 -> -0.040633775 | O24: =M24+N24 -> -0.078360263 | P24: =O24*2.804471 -> -0.21975909 | Q24: Due to higher weight to inflation coefficient
A25: Australia | B25: 22 | C25: 21.398345 | D25: 21.263648 | E25: =D25-C25 -> -0.1346965 | F25: 0.3 | G25: 21.563648 | H25: AAA | I25: KAIMIN KHAW | J25: 1.523677 | K25: 1.5355528 | L25: 1.4983284 | M25: =K25-J25 -> 0.011875844 | N25: =L25-K25 -> -0.037224448 | O25: =M25+N25 -> -0.025348605 | P25: =O25*2.804471 -> -0.071089427
A26: New Zealand | B26: 21.333333 | C26: 20.146832 | D26: 20.017221 | E26: =D26-C26 -> -0.12961173 | F26: 0.5 | G26: 20.517221 | H26: AA+ | I26: KAIMIN KHAW | J26: 1.7121728 | K26: 1.718652 | L26: 1.6817429 | M26: =K26-J26 -> 0.0064791924 | N26: =L26-K26 -> -0.03690917 | O26: =M26+N26 -> -0.030429978 | P26: =O26*2.804471 -> -0.08533999
A27: South Africa | B27: 10.333333 | C27: 11.835041 | D27: 11.937094 | E27: =D27-C27 -> 0.10205268 | F27: 0.5 | G27: 12.437094 | H27: BB+ | I27: HASSAN MALIK | J27: -0.29585497 | K27: -0.29134367 | L27: -0.28694899 | M27: =K27-J27 -> 0.0045113023 | N27: =L27-K27 -> 0.0043946763 | O27: =M27+N27 -> 0.0089059786 | P27: =O27*2.804471 -> 0.024976559
A28: Argentina | B28: 5.6666667 | C28: 8.5183684 | D28: 8.5219663 | E28: =D28-C28 -> 0.0035979133 | F28: -2.5 | G28: 6.0219663 | H28: CCC+ | I28: GREGORY HADJIAN | J28: -0.40125153 | K28: -0.29255747 | L28: -0.26466684 | M28: =K28-J28 -> 0.10869405 | N28: =L28-K28 -> 0.027890635 | O28: =M28+N28 -> 0.13658469 | P28: =O28*2.804471 -> 0.3830478
A29: Bolivia | B29: 3.6666667 | C29: 5.8755299 | D29: 6.3757781 | E29: =D29-C29 -> 0.50024824 | F29: -2.75 | G29: 3.6257781 | H29: CCC- | I29: GREGORY HADJIAN | J29: -0.99291646 | K29: -1.0056255 | L29: -1.1340894 | M29: =K29-J29 -> -0.012709062 | N29: =L29-K29 -> -0.12846386 | O29: =M29+N29 -> -0.14117292 | P29: =O29*2.804471 -> -0.39591536 | Q29: Sharp improvement in reserve buffers post data update
A30: Brazil | B30: 11.333333 | C30: 12.724257 | D30: 12.783663 | E30: =D30-C30 -> 0.059406075 | F30: -1 | G30: 11.783663 | H30: BB+ | I30: GREGORY HADJIAN | J30: -0.48766703 | K30: -0.50865034 | L30: -0.4855316 | M30: =K30-J30 -> -0.020983309 | N30: =L30-K30 -> 0.02311874 | O30: =M30+N30 -> 0.0021354309 | P30: =O30*2.804471 -> 0.0059887539
A31: Chile | B31: 16.666667 | C31: 15.923479 | D31: 15.965811 | E31: =D31-C31 -> 0.042331927 | F31: 0 | G31: 15.965811 | H31: A- | I31: GREGORY HADJIAN | J31: 0.62328809 | K31: 0.66202218 | L31: 0.66084981 | M31: =K31-J31 -> 0.038734094 | N31: =L31-K31 -> -0.0011723717 | O31: =M31+N31 -> 0.037561723 | P31: =O31*2.804471 -> 0.10534076
A32: Colombia | B32: 12 | C32: 12.133574 | D32: 11.801764 | E32: =D32-C32 -> -0.33181047 | F32: -1.5 | G32: 10.301764 | H32: BB- | I32: GREGORY HADJIAN | J32: -0.41284555 | K32: -0.48023923 | L32: -0.54717886 | M32: =K32-J32 -> -0.067393682 | N32: =L32-K32 -> -0.06693963 | O32: =M32+N32 -> -0.13433331 | P32: =O32*2.804471 -> -0.37673388
A33: Costa Rica | B33: 10.666667 | C33: 13.759663 | D33: 14.062246 | E33: =D33-C33 -> 0.30258223 | F33: -1.25 | G33: 12.812246 | H33: BBB- | I33: GREGORY HADJIAN | J33: 0.54861199 | K33: 0.65229291 | L33: 0.62275776 | M33: =K33-J33 -> 0.10368092 | N33: =L33-K33 -> -0.029535152 | O33: =M33+N33 -> 0.074145765 | P33: =O33*2.804471 -> 0.20793965
A34: Dominican Republic | B34: 10.666667 | C34: 11.84615 | D34: 12.091648 | E34: =D34-C34 -> 0.24549807 | F34: -0.25 | G34: 11.841648 | H34: BB+ | I34: GREGORY HADJIAN | J34: -0.11320813 | K34: -0.16774065 | L34: -0.058754814 | M34: =K34-J34 -> -0.054532519 | N34: =L34-K34 -> 0.10898583 | O34: =M34+N34 -> 0.054453315 | P34: =O34*2.804471 -> 0.15271274
A35: Ecuador | B35: 5.6666667 | C35: 8.702736 | D35: 8.3999594 | E35: =D35-C35 -> -0.30277662 | F35: -2.75 | G35: 5.6499594 | H35: CCC+ | I35: GREGORY HADJIAN | J35: -0.76690152 | K35: -0.70641765 | L35: -0.82496177 | M35: =K35-J35 -> 0.060483865 | N35: =L35-K35 -> -0.11854412 | O35: =M35+N35 -> -0.058060251 | P35: =O35*2.804471 -> -0.16282829 | Q35: Reweighting of defaut coefficient
A36: El Salvador | B36: 7 | C36: 6.297293 | D36: 5.7739379 | E36: =D36-C36 -> -0.52335506 | F36: 0.75 | G36: 6.5239379 | H36: B- | I36: GREGORY HADJIAN | J36: -0.47637359 | K36: -0.59835748 | L36: -0.62679652 | M36: =K36-J36 -> -0.12198388 | N36: =L36-K36 -> -0.028439043 | O36: =M36+N36 -> -0.15042292 | P36: =O36*2.804471 -> -0.42185673
A37: Guatemala | B37: 12 | C37: 10.689704 | D37: 10.969666 | E37: =D37-C37 -> 0.27996174 | F37: 1 | G37: 11.969666 | H37: BB+ | I37: GREGORY HADJIAN | J37: -0.93160879 | K37: -0.92804608 | L37: -0.88361184 | M37: =K37-J37 -> 0.0035627118 | N37: =L37-K37 -> 0.044434234 | O37: =M37+N37 -> 0.047996945 | P37: =O37*2.804471 -> 0.13460604
A38: Honduras | B38: 9.5 | C38: 8.9685337 | D38: 8.8087696 | E38: =D38-C38 -> -0.15976411 | F38: 0 | G38: 8.8087696 | H38: B+ | I38: GREGORY HADJIAN | J38: -0.99174471 | K38: -1.0216101 | L38: -1.0839169 | M38: =K38-J38 -> -0.029865428 | N38: =L38-K38 -> -0.062306751 | O38: =M38+N38 -> -0.092172179 | P38: =O38*2.804471 -> -0.2584942
A39: Mexico | B39: 13.666667 | C39: 12.534224 | D39: 12.265758 | E39: =D39-C39 -> -0.26846526 | F39: 0.5 | G39: 12.765758 | H39: BBB- | I39: GREGORY HADJIAN | J39: -0.71266744 | K39: -0.75577651 | L39: -0.84145677 | M39: =K39-J39 -> -0.043109064 | N39: =L39-K39 -> -0.08568026 | O39: =M39+N39 -> -0.12878932 | P39: =O39*2.804471 -> -0.36118593
A40: Nicaragua | B40: 8.3333333 | C40: 6.7228111 | D40: 6.245288 | E40: =D40-C40 -> -0.47752312 | F40: 0 | G40: 6.245288 | H40: CCC+ | I40: Not covered | J40: -1.2944628 | K40: -1.3557762 | L40: -1.4409284 | M40: =K40-J40 -> -0.061313449 | N40: =L40-K40 -> -0.085152167 | O40: =M40+N40 -> -0.14646562 | P40: =O40*2.804471 -> -0.41075857
A41: Panama | B41: 12.666667 | C41: 11.675954 | D41: 11.875909 | E41: =D41-C41 -> 0.1999549 | F41: -0.1 | G41: 11.775909 | H41: BB+ | I41: GREGORY HADJIAN | J41: -0.21938553 | K41: -0.16141605 | L41: -0.16571271 | M41: =K41-J41 -> 0.05796948 | N41: =L41-K41 -> -0.0042966633 | O41: =M41+N41 -> 0.053672817 | P41: =O41*2.804471 -> 0.15052386
A42: Paraguay | B42: 12.333333 | C42: 10.489497 | D42: 10.379036 | E42: =D42-C42 -> -0.11046089 | F42: 2.25 | G42: 12.629036 | H42: BBB- | I42: GREGORY HADJIAN | J42: -0.53916181 | K42: -0.59654359 | L42: -0.60531442 | M42: =K42-J42 -> -0.057381783 | N42: =L42-K42 -> -0.008770825 | O42: =M42+N42 -> -0.066152608 | P42: =O42*2.804471 -> -0.18552307
A43: Peru | B43: 14 | C43: 12.809185 | D43: 12.786463 | E43: =D43-C43 -> -0.022722585 | F43: 0.75 | G43: 13.536463 | H43: BBB | I43: GREGORY HADJIAN | J43: -0.52640665 | K43: -0.51966761 | L43: -0.5480991 | M43: =K43-J43 -> 0.0067390347 | N43: =L43-K43 -> -0.028431484 | O43: =M43+N43 -> -0.021692449 | P43: =O43*2.804471 -> -0.060835846
A44: Uruguay | B44: 14.666667 | C44: 13.890368 | D44: 13.867454 | E44: =D44-C44 -> -0.02291416 | F44: 0 | G44: 13.867454 | H44: BBB | I44: GREGORY HADJIAN | J44: 0.93445807 | K44: 1.0081235 | L44: 0.97591837 | M44: =K44-J44 -> 0.073665472 | N44: =L44-K44 -> -0.032205171 | O44: =M44+N44 -> 0.041460301 | P44: =O44*2.804471 -> 0.11627421
A45: Venezuela | B45: 1 | C45: -0.80261715 | D45: -1.1667272 | E45: =D45-C45 -> -0.36411008 | F45: 0 | G45: 1 | H45: D | I45: GREGORY HADJIAN | J45: -2.0540953 | K45: -2.0267007 | L45: -2.1799606 | M45: =K45-J45 -> 0.027394544 | N45: =L45-K45 -> -0.15325985 | O45: =M45+N45 -> -0.12586531 | P45: =O45*2.804471 -> -0.3529856
A46: Barbados | B46: 8.3333333 | C46: 9.4886257 | D46: 9.5286985 | E46: =D46-C46 -> 0.040072775 | F46: -0.75 | G46: 8.7786985 | H46: B+ | I46: GREGORY HADJIAN | J46: 0.74263616 | K46: 0.78029593 | L46: 0.78480038 | M46: =K46-J46 -> 0.037659775 | N46: =L46-K46 -> 0.0045044447 | O46: =M46+N46 -> 0.042164219 | P46: =O46*2.804471 -> 0.11824833
A47: Belize | B47: 6.5 | C47: 6.0014046 | D47: 6.0312688 | E47: =D47-C47 -> 0.029864204 | F47: 0 | G47: 6.0312688 | H47: CCC+ | I47: Not covered | J47: -0.26556218 | K47: -0.20827073 | L47: -0.22331691 | M47: =K47-J47 -> 0.057291449 | N47: =L47-K47 -> -0.015046177 | O47: =M47+N47 -> 0.042245272 | P47: =O47*2.804471 -> 0.11847564
... A55: Jordan | B55: 10 | C55: 9.935072 | D55: 9.9644323 | E55: =D55-C55 -> 0.029360322 | F55: -0.4 | G55: 9.5644323 | H55: BB- | I55: RAMSEY ANDRAWIS | J55: -0.18831597 | K55: -0.21216038 | L55: -0.21905894 | M55: =K55-J55 -> -0.023844402 | N55: =L55-K55 -> -0.006898563 | O55: =M55+N55 -> -0.030742965 | P55: =O55*2.804471 -> -0.086217753
A56: Kuwait | B56: 18.333333 | C56: 19.524028 | D56: 19.203784 | E56: =D56-C56 -> -0.32024386 | F56: -2.5 | G56: 16.703784 | H56: A | I56: RAMSEY ANDRAWIS | J56: -0.049126405 | K56: -0.04553989 | L56: -0.042925366 | M56: =K56-J56 -> 0.0035865154 | N56: =L56-K56 -> 0.0026145236 | O56: =M56+N56 -> 0.006201039 | P56: =O56*2.804471 -> 0.017390634 | Q56: Driven by smaller fiscal perf coefficient in re-weighting
...

Sheet select_country
B1: Select Country | C1: Bolivia
B2: Year | C2: 2025
B4: Factor View
D5: Oct (before) | G5: Dec (after WGI changes)
B6: Short Name | C6: Long Name | D6: Coeff | E6: Z-Score | F6: Rating Impact | G6: Coeff | H6: Z-Score | I6: Rating Impact | J6: Delta
B7: const | C7: Constant | D7: 12.695933 | E7: - | F7: =D7 -> 12.695933 | G7: 12.691923 | H7: - | I7: =G7 -> 12.691923 | J7: =I7-F7 -> -0.0040107437
B8: wealth_factor | C8: Wealth (5%) | D8: 0.50759205 | E8: =INDEX('2025_oct_transform'!$C$1:$AQ$139,MATCH($C$1,'2025_oct_transform'!$C$1:$C$139,0),MATCH($B8,'2025_oct_transform'!$C$1:$AQ$1,0)) -> -0.54654873 | F8: =D8*E8 -> -0.27742379 | G8: 0.53027255 | H8: =INDEX('2025_dec_transform'!$C$1:$AQ$139,MATCH($C$1,'2025_dec_transform'!$C$1:$C$139,0),MATCH($B8,'2025_dec_transform'!$C$1:$AQ$1,0)) -> -0.54654873 | I8: =G8*H8 -> -0.28981979 | J8: =I8-F8 -> -0.012395996
B9: size_factor | C9: Size (18%) | D9: 1.6047043 | E9: =INDEX('2025_oct_transform'!$C$1:$AQ$139,MATCH($C$1,'2025_oct_transform'!$C$1:$C$139,0),MATCH($B9,'2025_oct_transform'!$C$1:$AQ$1,0)) -> -0.40458579 | F9: =D9*E9 -> -0.64924056 | G9: 1.5749904 | H9: =INDEX('2025_dec_transform'!$C$1:$AQ$139,MATCH($C$1,'2025_dec_transform'!$C$1:$C$139,0),MATCH($B9,'2025_dec_transform'!$C$1:$AQ$1,0)) -> -0.40458579 | I9: =G9*H9 -> -0.63721875 | J9: =I9-F9 -> 0.012021817
B10: growth_factor | C10: Growth (2%) | D10: 0.14465344 | E10: =INDEX('2025_oct_transform'!$C$1:$AQ$139,MATCH($C$1,'2025_oct_transform'!$C$1:$C$139,0),MATCH($B10,'2025_oct_transform'!$C$1:$AQ$1,0)) -> -1.0103516 | F10: =D10*E10 -> -0.14615084 | G10: 0.13008491 | H10: =INDEX('2025_dec_transform'!$C$1:$AQ$139,MATCH($C$1,'2025_dec_transform'!$C$1:$C$139,0),MATCH($B10,'2025_dec_transform'!$C$1:$AQ$1,0)) -> -1.0103516 | I10: =G10*H10 -> -0.1314315 | J10: =I10-F10 -> 0.014719338
B11: inflation_factor | C11: Inflation (3%) | D11: 0.27236765 | E11: =INDEX('2025_oct_transform'!$C$1:$AQ$139,MATCH($C$1,'2025_oct_transform'!$C$1:$C$139,0),MATCH($B11,'2025_oct_transform'!$C$1:$AQ$1,0)) -> -0.74028236 | F11: =D11*E11 -> -0.20162897 | G11: 0.30518536 | H11: =INDEX('2025_dec_transform'!$C$1:$AQ$139,MATCH($C$1,'2025_dec_transform'!$C$1:$C$139,0),MATCH($B11,'2025_dec_transform'!$C$1:$AQ$1,0)) -> -0.74028236 | I11: =G11*H11 -> -0.22592334 | J11: =I11-F11 -> -0.024294369
B12: default_factor | C12: Default History (9%) | D12: 0.81804555 | E12: =INDEX('2025_oct_transform'!$C$1:$AQ$139,MATCH($C$1,'2025_oct_transform'!$C$1:$C$139,0),MATCH($B12,'2025_oct_transform'!$C$1:$AQ$1,0)) -> 0.30213082 | F12: =D12*E12 -> 0.24715677 | G12: 0.87885606 | H12: =INDEX('2025_dec_transform'!$C$1:$AQ$139,MATCH($C$1,'2025_dec_transform'!$C$1:$C$139,0),MATCH($B12,'2025_dec_transform'!$C$1:$AQ$1,0)) -> 0.30213082 | I12: =G12*H12 -> 0.2655295 | J12: =I12-F12 -> 0.01837273
B13: governance_factor | C13: Governance (32%) | D13: 2.8789941 | E13: =INDEX('2025_oct_transform'!$C$1:$AQ$139,MATCH($C$1,'2025_oct_transform'!$C$1:$C$139,0),MATCH($B13,'2025_oct_transform'!$C$1:$AQ$1,0)) -> -0.99291646 | F13: =D13*E13 -> -2.8586006 | G13: 2.8044707 | H13: =INDEX('2025_dec_transform'!$C$1:$AQ$139,MATCH($C$1,'2025_dec_transform'!$C$1:$C$139,0),MATCH($B13,'2025_dec_transform'!$C$1:$AQ$1,0)) -> -1.1340894 | I13: =G13*H13 -> -3.1805204 | J13: =I13-F13 -> -0.32191986
B14: fiscalperf_factor | C14: Fiscal Performance (7%) | D14: 0.65335151 | E14: =INDEX('2025_oct_transform'!$C$1:$AQ$139,MATCH($C$1,'2025_oct_transform'!$C$1:$C$139,0),MATCH($B14,'2025_oct_transform'!$C$1:$AQ$1,0)) -> -0.99802823 | F14: =D14*E14 -> -0.65206325 | G14: 0.5796163 | H14: =INDEX('2025_dec_transform'!$C$1:$AQ$139,MATCH($C$1,'2025_dec_transform'!$C$1:$C$139,0),MATCH($B14,'2025_dec_transform'!$C$1:$AQ$1,0)) -> -0.99802879 | I14: =G14*H14 -> -0.57847375 | J14: =I14-F14 -> 0.073589494
B15: govdebt_factor | C15: Government Debt (10%) | D15: 0.91025734 | E15: =INDEX('2025_oct_transform'!$C$1:$AQ$139,MATCH($C$1,'2025_oct_transform'!$C$1:$C$139,0),MATCH($B15,'2025_oct_transform'!$C$1:$AQ$1,0)) -> -0.99062149 | F15: =D15*E15 -> -0.90172048 | G15: 0.88139076 | H15: =INDEX('2025_dec_transform'!$C$1:$AQ$139,MATCH($C$1,'2025_dec_transform'!$C$1:$C$139,0),MATCH($B15,'2025_dec_transform'!$C$1:$AQ$1,0)) -> -0.99062149 | I15: =G15*H15 -> -0.87312462 | J15: =I15-F15 -> 0.028595851
B16: extperf_factor | C16: External Performance (5%) | D16: 0.46481235 | E16: =INDEX('2025_oct_transform'!$C$1:$AQ$139,MATCH($C$1,'2025_oct_transform'!$C$1:$C$139,0),MATCH($B16,'2025_oct_transform'!$C$1:$AQ$1,0)) -> 0.098618921 | F16: =D16*E16 -> 0.045839293 | G16: 0.47302681 | H16: =INDEX('2025_dec_transform'!$C$1:$AQ$139,MATCH($C$1,'2025_dec_transform'!$C$1:$C$139,0),MATCH($B16,'2025_dec_transform'!$C$1:$AQ$1,0)) -> 0.098618921 | I16: =G16*H16 -> 0.046649393 | J16: =I16-F16 -> 0.00081010045
B17: reservebuffer_factor | C17: FX Reserves (4%) | D17: 0.35395378 | E17: =INDEX('2025_oct_transform'!$C$1:$AQ$139,MATCH($C$1,'2025_oct_transform'!$C$1:$C$139,0),MATCH($B17,'2025_oct_transform'!$C$1:$AQ$1,0)) -> -3.3590278 | F17: =D17*E17 -> -1.1889406 | G17: 0.3484954 | H17: =INDEX('2025_dec_transform'!$C$1:$AQ$139,MATCH($C$1,'2025_dec_transform'!$C$1:$C$139,0),MATCH($B17,'2025_dec_transform'!$C$1:$AQ$1,0)) -> -1.3162626 | I17: =G17*H17 -> -0.45871148 | J17: =I17-F17 -> 0.73022909
B18: reservestatus_factor | C18: Reserve Currency Status (5%) | D18: 0.45274543 | E18: =INDEX('2025_oct_transform'!$C$1:$AQ$139,MATCH($C$1,'2025_oct_transform'!$C$1:$C$139,0),MATCH($B18,'2025_oct_transform'!$C$1:$AQ$1,0)) -> -0.52486557 | F18: =D18*E18 -> -0.23763049 | G18: 0.48221815 | H18: =INDEX('2025_dec_transform'!$C$1:$AQ$139,MATCH($C$1,'2025_dec_transform'!$C$1:$C$139,0),MATCH($B18,'2025_dec_transform'!$C$1:$AQ$1,0)) -> -0.52486557 | I18: =G18*H18 -> -0.25309971 | J18: =I18-F18 -> -0.015469217
B19: Model Rating | F19: =SUM(F7:F18) -> 5.8755299 | I19: =SUM(I7:I18) -> 6.3757781 | J19: =I19-F19 -> 0.50024824
E20: check | F20: =INDEX('2025_oct_transform'!$C$1:$AQ$139,MATCH($C$1,'2025_oct_transform'!$C$1:$C$139,0),MATCH("predicted_rating",'2025_oct_transform'!$C$1:$AQ$1,0)) -> 5.8755299 | H20: check | I20: =INDEX('2025_dec_transform'!$C$1:$AQ$139,MATCH($C$1,'2025_dec_transform'!$C$1:$C$139,0),MATCH("predicted_rating",'2025_dec_transform'!$C$1:$AQ$1,0)) -> 6.3757781 | J20: =SUM(J7:J18) -> 0.50024824
B23: Raw Variable View
D24: Oct (before) | F24: Dec (after WGI changes)
A25: Short Name | B25: Factor | C25: Constituent Variables | D25: Raw | E25: Z-Score | F25: Raw | G25: Z-score | H25: Raw Delta | I25: Z-Score Delta
B26: Intercept | C26: Baseline Rating | D26: - | E26: - | F26: - | G26: - | H26: - | I26: -
A27: ngdp_pc | B27: Wealth (%) | C27: Nominal GDP per capita (US$) | D27: =INDEX('2025_oct_raw'!$C$1:$AK$139,MATCH($C$1,'2025_oct_raw'!$C$1:$C$139,0),MATCH($A27,'2025_oct_raw'!$C$1:$AK$1,0)) -> 4585.184 | E27: =INDEX('2025_oct_transform'!$C$1:$AQ$139,MATCH($C$1,'2025_oct_transform'!$C$1:$C$139,0),MATCH($A27,'2025_oct_transform'!$C$1:$AQ$1,0)) -> -0.54654873 | F27: =INDEX('2025_dec_raw'!$C$1:$AK$139,MATCH($C$1,'2025_dec_raw'!$C$1:$C$139,0),MATCH($A27,'2025_dec_raw'!$C$1:$AK$1,0)) -> 4585.184 | G27: =INDEX('2025_dec_transform'!$C$1:$AQ$139,MATCH($C$1,'2025_dec_transform'!$C$1:$C$139,0),MATCH($A27,'2025_dec_transform'!$C$1:$AQ$1,0)) -> -0.54654873 | H27: =F27-D27 -> 0 | I27: =G27-E27 -> 0
A28: ngdp | B28: Size (18%) | C28: Nominal GDP (US$ bil) | D28: =INDEX('2025_oct_raw'!$C$1:$AK$139,MATCH($C$1,'2025_oct_raw'!$C$1:$C$139,0),MATCH($A28,'2025_oct_raw'!$C$1:$AK$1,0)) -> 57.086 | E28: =INDEX('2025_oct_transform'!$C$1:$AQ$139,MATCH($C$1,'2025_oct_transform'!$C$1:$C$139,0),MATCH($A28,'2025_oct_transform'!$C$1:$AQ$1,0)) -> -0.40458579 | F28: =INDEX('2025_dec_raw'!$C$1:$AK$139,MATCH($C$1,'2025_dec_raw'!$C$1:$C$139,0),MATCH($A28,'2025_dec_raw'!$C$1:$AK$1,0)) -> 57.086 | G28: =INDEX('2025_dec_transform'!$C$1:$AQ$139,MATCH($C$1,'2025_dec_transform'!$C$1:$C$139,0),MATCH($A28,'2025_dec_transform'!$C$1:$AQ$1,0)) -> -0.40458579 | H28: =F28-D28 -> 0 | I28: =G28-E28 -> 0
A29: growth_avg | B29: Growth (2%) | C29: Average Growth t-5 to t+4 (%) | D29: =INDEX('2025_oct_raw'!$C$1:$AK$139,MATCH($C$1,'2025_oct_raw'!$C$1:$C$139,0),MATCH($A29,'2025_oct_raw'!$C$1:$AK$1,0)) -> 0.89857143 | E29: =INDEX('2025_oct_transform'!$C$1:$AQ$139,MATCH($C$1,'2025_oct_transform'!$C$1:$C$139,0),MATCH($A29,'2025_oct_transform'!$C$1:$AQ$1,0)) -> -1.0103516 | F29: =INDEX('2025_dec_raw'!$C$1:$AK$139,MATCH($C$1,'2025_dec_raw'!$C$1:$C$139,0),MATCH($A29,'2025_dec_raw'!$C$1:$AK$1,0)) -> 0.89857143 | G29: =INDEX('2025_dec_transform'!$C$1:$AQ$139,MATCH($C$1,'2025_dec_transform'!$C$1:$C$139,0),MATCH($A29,'2025_dec_transform'!$C$1:$AQ$1,0)) -> -1.0103516 | H29: =F29-D29 -> 0 | I29: =G29-E29 -> 0
A30: inf_avg | B30: Inflation (3%) | C30: Average Inflation t-5 to t+4 (%) | D30: =INDEX('2025_oct_raw'!$C$1:$AK$139,MATCH($C$1,'2025_oct_raw'!$C$1:$C$139,0),MATCH($A30,'2025_oct_raw'!$C$1:$AK$1,0)) -> 8.5318571 | E30: =INDEX('2025_oct_transform'!$C$1:$AQ$139,MATCH($C$1,'2025_oct_transform'!$C$1:$C$139,0),MATCH($A30,'2025_oct_transform'!$C$1:$AQ$1,0)) -> 0.74028236 | F30: =INDEX('2025_dec_raw'!$C$1:$AK$139,MATCH($C$1,'2025_dec_raw'!$C$1:$C$139,0),MATCH($A30,'2025_dec_raw'!$C$1:$AK$1,0)) -> 8.5318571 | G30: =INDEX('2025_dec_transform'!$C$1:$AQ$139,MATCH($C$1,'2025_dec_transform'!$C$1:$C$139,0),MATCH($A30,'2025_dec_transform'!$C$1:$AQ$1,0)) -> 0.74028236 | H30: =F30-D30 -> 0 | I30: =G30-E30 -> 0
A31: default_factor | B31: Default History (9%) | C31: Average of Default History and Default Decay | D31: - | E31: =INDEX('2025_oct_transform'!$C$1:$AQ$139,MATCH($C$1,'2025_oct_transform'!$C$1:$C$139,0),MATCH($A31,'2025_oct_transform'!$C$1:$AQ$1,0)) -> 0.30213082 | F31: - | G31: =INDEX('2025_dec_transform'!$C$1:$AQ$139,MATCH($C$1,'2025_dec_transform'!$C$1:$C$139,0),MATCH($A31,'2025_dec_transform'!$C$1:$AQ$1,0)) -> 0.30213082 | H31: - | I31: =G31-E31 -> 0
A32: default_hist | C32: Default history dummy. 1 if ever defaulted before 0 otherwise. | D32: =INDEX('2025_oct_raw'!$C$1:$AK$139,MATCH($C$1,'2025_oct_raw'!$C$1:$C$139,0),MATCH($A32,'2025_oct_raw'!$C$1:$AK$1,0)) -> 0 | E32: =INDEX('2025_oct_transform'!$C$1:$AQ$139,MATCH($C$1,'2025_oct_transform'!$C$1:$C$139,0),MATCH($A32,'2025_oct_transform'!$C$1:$AQ$1,0)) -> -0.3610543 | F32: =INDEX('2025_dec_raw'!$C$1:$AK$139,MATCH($C$1,'2025_dec_raw'!$C$1:$C$139,0),MATCH($A32,'2025_dec_raw'!$C$1:$AK$1,0)) -> 0 | G32: =INDEX('2025_dec_transform'!$C$1:$AQ$139,MATCH($C$1,'2025_dec_transform'!$C$1:$C$139,0),MATCH($A32,'2025_dec_transform'!$C$1:$AQ$1,0)) -> -0.3610543 | H32: =F32-D32 -> 0 | I32: =G32-E32 -> 0
A33: default_decay | C33: Default Decay. 1 at point of default. Decays to 0.5 in 4.3 years. | D33: =INDEX('2025_oct_raw'!$C$1:$AK$139,MATCH($C$1,'2025_oct_raw'!$C$1:$C$139,0),MATCH($A33,'2025_oct_raw'!$C$1:$AK$1,0)) -> 0 | E33: =INDEX('2025_oct_transform'!$C$1:$AQ$139,MATCH($C$1,'2025_oct_transform'!$C$1:$C$139,0),MATCH($A33,'2025_oct_transform'!$C$1:$AQ$1,0)) -> -0.24320733 | F33: =INDEX('2025_dec_raw'!$C$1:$AK$139,MATCH($C$1,'2025_dec_raw'!$C$1:$C$139,0),MATCH($A33,'2025_dec_raw'!$C$1:$AK$1,0)) -> 0 | G33: =INDEX('2025_dec_transform'!$C$1:$AQ$139,MATCH($C$1,'2025_dec_transform'!$C$1:$C$139,0),MATCH($A33,'2025_dec_transform'!$C$1:$AQ$1,0)) -> -0.24320733 | H33: =F33-D33 -> 0 | I33: =G33-E33 -> 0
A34: governance_factor | B34: Governance (32%) | C34: Average of 6 WGI Indicators | D34: - | E34: =INDEX('2025_oct_transform'!$C$1:$AQ$139,MATCH($C$1,'2025_oct_transform'!$C$1:$C$139,0),MATCH($A34,'2025_oct_transform'!$C$1:$AQ$1,0)) -> -0.99291646 | F34: - | G34: =INDEX('2025_dec_transform'!$C$1:$AQ$139,MATCH($C$1,'2025_dec_transform'!$C$1:$C$139,0),MATCH($A34,'2025_dec_transform'!$C$1:$AQ$1,0)) -> -1.1340894 | H34: - | I34: =G34-E34 -> -0.14117292
A35: voice_acct | C35: Voice and Accountability (cross section z-score) | D35: =INDEX('2025_oct_raw'!$C$1:$AK$139,MATCH($C$1,'2025_oct_raw'!$C$1:$C$139,0),MATCH($A35,'2025_oct_raw'!$C$1:$AK$1,0)) -> -0.265191 | E35: =INDEX('2025_oct_transform'!$C$1:$AQ$139,MATCH($C$1,'2025_oct_transform'!$C$1:$C$139,0),MATCH($A35,'2025_oct_transform'!$C$1:$AQ$1,0)) -> -0.44968671 | F35: =INDEX('2025_dec_raw'!$C$1:$AK$139,MATCH($C$1,'2025_dec_raw'!$C$1:$C$139,0),MATCH($A35,'2025_dec_raw'!$C$1:$AK$1,0)) -> -0.439764 | G35: =INDEX('2025_dec_transform'!$C$1:$AQ$139,MATCH($C$1,'2025_dec_transform'!$C$1:$C$139,0),MATCH($A35,'2025_dec_transform'!$C$1:$AQ$1,0)) -> -0.63148476 | H35: =F35-D35 -> -0.174573 | I35: =G35-E35 -> -0.18179804
A36: pol_stab | C36: Political Stability (cross section z-score) | D36: =INDEX('2025_oct_raw'!$C$1:$AK$139,MATCH($C$1,'2025_oct_raw'!$C$1:$C$139,0),MATCH($A36,'2025_oct_raw'!$C$1:$AK$1,0)) -> -0.313184 | E36: =INDEX('2025_oct_transform'!$C$1:$AQ$139,MATCH($C$1,'2025_oct_transform'!$C$1:$C$139,0),MATCH($A36,'2025_oct_transform'!$C$1:$AQ$1,0)) -> -0.40383874 | F36: =INDEX('2025_dec_raw'!$C$1:$AK$139,MATCH($C$1,'2025_dec_raw'!$C$1:$C$139,0),MATCH($A36,'2025_dec_raw'!$C$1:$AK$1,0)) -> -0.546036 | G36: =INDEX('2025_dec_transform'!$C$1:$AQ$139,MATCH($C$1,'2025_dec_transform'!$C$1:$C$139,0),MATCH($A36,'2025_dec_transform'!$C$1:$AQ$1,0)) -> -0.69802322 | H36: =F36-D36 -> -0.232852 | I36: =G36-E36 -> -0.29418448
A37: gov_eff | C37: Government Effectiveness (cross section z-score) | D37: =INDEX('2025_oct_raw'!$C$1:$AK$139,MATCH($C$1,'2025_oct_raw'!$C$1:$C$139,0),MATCH($A37,'2025_oct_raw'!$C$1:$AK$1,0)) -> -0.639481 | E37: =INDEX('2025_oct_transform'!$C$1:$AQ$139,MATCH($C$1,'2025_oct_transform'!$C$1:$C$139,0),MATCH($A37,'2025_oct_transform'!$C$1:$AQ$1,0)) -> -0.98282211 | F37: =INDEX('2025_dec_raw'!$C$1:$AK$139,MATCH($C$1,'2025_dec_raw'!$C$1:$C$139,0),MATCH($A37,'2025_dec_raw'!$C$1:$AK$1,0)) -> -0.610417 | G37: =INDEX('2025_dec_transform'!$C$1:$AQ$139,MATCH($C$1,'2025_dec_transform'!$C$1:$C$139,0),MATCH($A37,'2025_dec_transform'!$C$1:$AQ$1,0)) -> -1.0457222 | H37: =F37-D37 -> 0.029064 | I37: =G37-E37 -> -0.062900053
A38: reg_qual | C38: Regulatory Quality (cross section z-score) | D38: =INDEX('2025_oct_raw'!$C$1:$AK$139,MATCH($C$1,'2025_oct_raw'!$C$1:$C$139,0),MATCH($A38,'2025_oct_raw'!$C$1:$AK$1,0)) -> -1.177119 | E38: =INDEX('2025_oct_transform'!$C$1:$AQ$139,MATCH($C$1,'2025_oct_transform'!$C$1:$C$139,0),MATCH($A38,'2025_oct_transform'!$C$1:$AQ$1,0)) -> -1.6557626 | F38: =INDEX('2025_dec_raw'!$C$1:$AK$139,MATCH($C$1,'2025_dec_raw'!$C$1:$C$139,0),MATCH($A38,'2025_dec_raw'!$C$1:$AK$1,0)) -> -1.25443 | G38: =INDEX('2025_dec_transform'!$C$1:$AQ$139,MATCH($C$1,'2025_dec_transform'!$C$1:$C$139,0),MATCH($A38,'2025_dec_transform'!$C$1:$AQ$1,0)) -> -1.7760799 | H38: =F38-D38 -> -0.077311 | I38: =G38-E38 -> -0.12031728
A39: rule_law | C39: Rule of Law (cross section z-score) | D39: =INDEX('2025_oct_raw'!$C$1:$AK$139,MATCH($C$1,'2025_oct_raw'!$C$1:$C$139,0),MATCH($A39,'2025_oct_raw'!$C$1:$AK$1,0)) -> -1.219338 | E39: =INDEX('2025_oct_transform'!$C$1:$AQ$139,MATCH($C$1,'2025_oct_transform'!$C$1:$C$139,0),MATCH($A39,'2025_oct_transform'!$C$1:$AQ$1,0)) -> -1.4791424 | F39: =INDEX('2025_dec_raw'!$C$1:$AK$139,MATCH($C$1,'2025_dec_raw'!$C$1:$C$139,0),MATCH($A39,'2025_dec_raw'!$C$1:$AK$1,0)) -> -1.267722 | G39: =INDEX('2025_dec_transform'!$C$1:$AQ$139,MATCH($C$1,'2025_dec_transform'!$C$1:$C$139,0),MATCH($A39,'2025_dec_transform'!$C$1:$AQ$1,0)) -> -1.4925143 | H39: =F39-D39 -> -0.048384 | I39: =G39-E39 -> -0.013371943
A40: cont_corrupt | C40: Control of Corruption (cross section z-score) | D40: =INDEX('2025_oct_raw'!$C$1:$AK$139,MATCH($C$1,'2025_oct_raw'!$C$1:$C$139,0),MATCH($A40,'2025_oct_raw'!$C$1:$AK$1,0)) -> -0.838301 | E40: =INDEX('2025_oct_transform'!$C$1:$AQ$139,MATCH($C$1,'2025_oct_transform'!$C$1:$C$139,0),MATCH($A40,'2025_oct_transform'!$C$1:$AQ$1,0)) -> -0.98624622 | F40: =INDEX('2025_dec_raw'!$C$1:$AK$139,MATCH($C$1,'2025_dec_raw'!$C$1:$C$139,0),MATCH($A40,'2025_dec_raw'!$C$1:$AK$1,0)) -> -0.997583 | G40: =INDEX('2025_dec_transform'!$C$1:$AQ$139,MATCH($C$1,'2025_dec_transform'!$C$1:$C$139,0),MATCH($A40,'2025_dec_transform'!$C$1:$AQ$1,0)) -> -1.1607119 | H40: =F40-D40 -> -0.159282 | I40: =G40-E40 -> -0.17446571
A41: fiscalperf_factor | B41: Fiscal Performance (7%) | C41: Average of Fiscal Balance, Govt Rev GDP, Interest to Rev | D41: - | E41: =INDEX('2025_oct_transform'!$C$1:$AQ$139,MATCH($C$1,'2025_oct_transform'!$C$1:$C$139,0),MATCH($A41,'2025_oct_transform'!$C$1:$AQ$1,0)) -> -0.99802823 | F41: - | G41: =INDEX('2025_dec_transform'!$C$1:$AQ$139,MATCH($C$1,'2025_dec_transform'!$C$1:$C$139,0),MATCH($A41,'2025_dec_transform'!$C$1:$AQ$1,0)) -> -0.99802879 | I41: =G41-E41 -> -5.6430916e-07
A42: fb_avg | C42: Average of Fiscal Balance 10Y Avg t-5 to t+4 (% of GDP) | D42: =INDEX('2025_oct_raw'!$C$1:$AK$139,MATCH($C$1,'2025_oct_raw'!$C$1:$C$139,0),MATCH($A42,'2025_oct_raw'!$C$1:$AK$1,0)) -> -11.042 | E42: =INDEX('2025_oct_transform'!$C$1:$AQ$139,MATCH($C$1,'2025_oct_transform'!$C$1:$C$139,0),MATCH($A42,'2025_oct_transform'!$C$1:$AQ$1,0)) -> -2.1377782 | F42: =INDEX('2025_dec_raw'!$C$1:$AK$139,MATCH($C$1,'2025_dec_raw'!$C$1:$C$139,0),MATCH($A42,'2025_dec_raw'!$C$1:$AK$1,0)) -> -11.042 | G42: =INDEX('2025_dec_transform'!$C$1:$AQ$139,MATCH($C$1,'2025_dec_transform'!$C$1:$C$139,0),MATCH($A42,'2025_dec_transform'!$C$1:$AQ$1,0)) -> -2.1377782 | H42: =F42-D42 -> 0 | I42: =G42-E42 -> 0
A43: gov_rev_gdp | C43: Government Revenue (% of GDP) | D43: =INDEX('2025_oct_raw'!$C$1:$AK$139,MATCH($C$1,'2025_oct_raw'!$C$1:$C$139,0),MATCH($A43,'2025_oct_raw'!$C$1:$AK$1,0)) -> 25.073 | E43: =INDEX('2025_oct_transform'!$C$1:$AQ$139,MATCH($C$1,'2025_oct_transform'!$C$1:$C$139,0),MATCH($A43,'2025_oct_transform'!$C$1:$AQ$1,0)) -> -0.3573749 | F43: =INDEX('2025_dec_raw'!$C$1:$AK$139,MATCH($C$1,'2025_dec_raw'!$C$1:$C$139,0),MATCH($A43,'2025_dec_raw'!$C$1:$AK$1,0)) -> 25.073 | G43: =INDEX('2025_dec_transform'!$C$1:$AQ$139,MATCH($C$1,'2025_dec_transform'!$C$1:$C$139,0),MATCH($A43,'2025_dec_transform'!$C$1:$AQ$1,0)) -> -0.3573749 | H43: =F43-D43 -> 0 | I43: =G43-E43 -> 0
...

Sheet Ratings
A1: name | B1: public_rating | C1: model_rating | D1: Adjustment | E1: LS_rating | F1: LS_letter | G1: distance_lower_bound | H1: ERV_Dot | I1: in ERV | J1: Analyst
A2: United States | B2: 21 | C2: 18.705977 | D2: 0 | E2: 18.705977 | F2: AA- | G2: 0.205977 | H2: ⚫ | I2: No | J2: BRIAN HORRIGAN
A3: United Kingdom | B3: 19.333333 | C3: 19.153396 | D3: 0 | E3: 19.153396 | F3: AA- | G3: 0.65339647 | H3: ⚫ | I3: No | J3: JON LEVY
A4: Austria | B4: 20.666667 | C4: 18.723972 | D4: 0 | E4: 18.723972 | F4: AA- | G4: 0.22397205 | H4: ⚫ | I4: No | J4: Not covered
A5: Belgium | B5: 19 | C5: 17.541837 | D5: 0 | E5: 17.541837 | F5: A+ | G5: 0.041836822 | H5: ⚫ | I5: No | J5: Not covered
A6: Denmark | B6: 22 | C6: 23.251883 | D6: 0 | E6: 22 | F6: AAA | G6: 1 | H6: ⚫ | I6: No | J6: Not covered
A7: France | B7: 18.666667 | C7: 17.913243 | D7: 0.2 | E7: 18.113243 | F7: A+ | G7: 0.61324323 | H7: ⚫ | I7: No | J7: JON LEVY
A8: Germany | B8: 22 | C8: 21.331576 | D8: 0.4 | E8: 21.731576 | F8: AAA | G8: 0.2315757 | H8: ⚫ | I8: No | J8: JON LEVY
A9: Italy | B9: 14.333333 | C9: 16.575605 | D9: 0 | E9: 16.575605 | F9: A | G9: 0.075605408 | H9: ⚫ | I9: No | J9: JON LEVY
A10: Luxembourg | B10: 22 | C10: 21.06722 | D10: 0 | E10: 21.06722 | F10: AA+ | G10: 0.56722023 | H10: ⚫ | I10: No | J10: Not covered
A11: Netherlands | B11: 22 | C11: 21.4562 | D11: 0 | E11: 21.4562 | F11: AA+ | G11: 0.95620032 | H11: ⚫ | I11: No | J11: Not covered
A12: Norway | B12: 22 | C12: 23.741085 | D12: 0 | E12: 22 | F12: AAA | G12: 1 | H12: ⚫ | I12: No | J12: JINGZHOU MENG
A13: Sweden | B13: 22 | C13: 21.812877 | D13: 0 | E13: 21.812877 | F13: AAA | G13: 0.31287702 | H13: ⚫ | I13: No | J13: JINGZHOU MENG
... A79: Vietnam | B79: 11.666667 | C79: 13.07901 | D79: 0 | E79: 13.07901 | F79: BBB- | G79: 0.57901001 | H79: ⚫ | I79: Yes | J79: HUANI ZHU
A80: Algeria | C80: 10.4754 | D80: 0 | E80: 10.4754 | F80: BB- | G80: 0.97539982 | H80: ⚫
A81: Angola | B81: 7 | C81: 7.9745947 | D81: -1 | E81: 6.9745947 | F81: B- | G81: 0.47459467 | H81: ⚫ | I81: Yes | J81: SAURABH LELE
A82: Botswana | B82: 15 | C82: 12.282028 | D82: 0 | E82: 12.282028 | F82: BB+ | G82: 0.78202798 | H82: ⚫ | I82: No | J82: Not covered
A83: Cameroon | B83: 7 | C83: 7.7166527 | D83: 0 | E83: 7.7166527 | F83: B | G83: 0.21665266 | H83: ⚫ | I83: Yes | J83: SAURABH LELE
A84: Cabo Verde | B84: 8 | C84: 9.5974388 | D84: 0 | E84: 9.5974388 | F84: BB- | G84: 0.097438838 | H84: ⚫ | I84: No | J84: Not covered
A85: Republic of Congo | B85: 5.6666667 | C85: 3.7726127 | D85: 0 | E85: 3.7726127 | F85: CCC- | G85: 0.27261269 | H85: ⚫ | I85: No | J85: Not covered
A86: Democratic Republic of the Congo | B86: 7 | C86: 6.3491191 | D86: 0 | E86: 6.3491191 | F86: CCC+ | G86: 0.84911914 | H86: ⚫ | I86: No | J86: Not covered
A87: Benin | B87: 9.3333333 | C87: 7.9366786 | D87: 0 | E87: 7.9366786 | F87: B | G87: 0.43667856 | H87: ⚫ | I87: No | J87: Not covered
A88: Ethiopia | B88: 2 | C88: 7.2218771 | D88: 0 | E88: 7.2218771 | F88: B- | G88: 0.72187713 | H88: ⚫ | I88: Yes | J88: SAURABH LELE
A89: Gabon | B89: 5 | C89: 7.6194959 | D89: -1.5 | E89: 6.1194959 | F89: CCC+ | G89: 0.61949592 | H89: ⚫ | I89: Yes | J89: SAURABH LELE
A90: Ghana | B90: 6.3333333 | C90: 7.3490591 | D90: -1 | E90: 6.3490591 | F90: CCC+ | G90: 0.84905914 | H90: ⚫ | I90: Yes | J90: SAURABH LELE
A91: Côte d'Ivoire | B91: 10.666667 | C91: 9.8343364 | D91: 1.5 | E91: 11.334336 | F91: BB | G91: 0.83433635 | H91: ⚫ | I91: Yes | J91: SAURABH LELE
A92: Kenya | B92: 7 | C92: 8.6955272 | D92: -0.5 | E92: 8.1955272 | F92: B | G92: 0.6955272 | H92: ⚫ | I92: Yes | J92: SAURABH LELE
... A139: Romania | B139: 13 | C139: 13.805774 | D139: -1.4 | E139: 12.405774 | F139: BB+ | G139: 0.90577398 | H139: ⚫ | I139: Yes | J139: RAMSEY ANDRAWIS

Sheet 2023_old
A1: cc | B1: year | C1: name | D1: rating | E1: predicted_rating | F1: resid | G1: wealth_factor | H1: size_factor | I1: growth_factor | J1: inflation_factor | K1: default_factor | L1: governance_factor | M1: fiscalperf_factor | N1: govdebt_factor | O1: extperf_factor | P1: reservebuffer_factor | Q1: reservestatus_factor | R1: ngdp_pc | S1: median_ngdp_pc | T1: detrend_median_ngdp_pc | U1: trend_median_ngdp_pc | V1: ngdp | W1: median_ngdp | X1: detrend_median_ngdp | Y1: trend_median_ngdp | Z1: growth_avg | AA1: inf_avg | AB1: default_hist | AC1: default_decay | AD1: voice_acct | AE1: pol_stab | AF1: gov_eff | AG1: reg_qual | AH1: rule_law | AI1: cont_corrupt | AJ1: fb_avg | AK1: gov_rev_gdp | AL1: ir_rev | AM1: gov_debt_gdp | AN1: cab_avg | AO1: reserve_gdp | AP1: import_cover | AQ1: reserve_fx
A2: 111 | B2: 2023 | C2: United States | D2: 21.333333 | E2: 19.029275 | F2: 2.3040584 | G2: 1.6614344 | H2: 2.8554324 | I2: -0.52759164 | J2: 0.28282165 | K2: 0.30213082 | L2: 0.90987171 | M2: -0.51474064 | N2: -1.7165755 | O2: -0.16133751 | P2: -2.3965533 | Q2: 1.9052497 | R2: 1.6614344 | S2: 9.1137513 | T2: 0.022102599 | U2: 9.0916487 | V2: 2.8554324 | W2: 4.6286621 | X2: 0.094936804 | Y2: 4.5337253 | Z2: -0.52759164 | AA2: -0.28282165 | AB2: -0.3610543 | AC2: -0.24320733 | AD2: 0.82446263 | AE2: 0.0058924098 | AF2: 1.0970561 | AG2: 1.2640173 | AH2: 1.2576697 | AI2: 1.0101322 | AJ2: -1.3046814 | AK2: 0.036896935 | AL2: -0.27643747 | AM2: 1.7165755 | AN2: -0.16133751 | AO2: -2.712037 | AP2: -2.0810697 | AQ2: 1.9052497
A3: 112 | B3: 2023 | C3: United Kingdom | D3: 19.333333 | E3: 19.233674 | F3: 0.099659818 | G3: 1.2704945 | H3: 1.7540306 | I3: -0.92463478 | J3: 0.24867021 | K3: 0.30213082 | L3: 1.1678865 | M3: 0.097672458 | N3: -1.1753189 | O3: -0.23399601 | P3: -0.60213319 | Q3: 1.9052497 | R3: 1.2704945 | S3: 9.1137513 | T3: 0.022102599 | U3: 9.0916487 | V3: 1.7540306 | W3: 4.6286621 | X3: 0.094936804 | Y3: 4.5337253 | Z3: -0.92463478 | AA3: -0.24867021 | AB3: -0.3610543 | AC3: -0.24320733 | AD3: 1.252749 | AE3: 0.58652216 | AF3: 1.0342592 | AG3: 1.4262373 | AH3: 1.3336252 | AI3: 1.3739263 | AJ3: -0.63404892 | AK3: 0.77305254 | AL3: 0.15401376 | AM3: 1.1753189 | AN3: -0.23399601 | AO3: -0.7002033 | AP3: -0.50406308 | AQ3: 1.9052497
A4: 122 | B4: 2023 | C4: Austria | D4: 21 | E4: 18.795248 | F4: 2.204752 | G4: 1.369164 | H4: 0.77017188 | I4: -0.83111527 | J4: 0.24309914 | K4: 0.30213082 | L4: 1.2393602 | M4: 0.77258859 | N4: -0.56838463 | O4: 0.30582854 | P4: -1.6526393 | Q4: 1.9052497 | R4: 1.369164 | S4: 9.1137513 | T4: 0.022102599 | U4: 9.0916487 | V4: 0.77017188 | W4: 4.6286621 | X4: 0.094936804 | Y4: 4.5337253 | Z4: -0.83111527 | AA4: -0.24309914 | AB4: -0.3610543 | AC4: -0.24320733 | AD4: 1.4195834 | AE4: 0.84131539 | AF4: 1.2196969 | AG4: 1.2272618 | AH4: 1.7077709 | AI4: 1.0205327 | AJ4: -0.0084995308 | AK4: 1.7049828 | AL4: 0.62128251 | AM4: 0.56838463 | AN4: 0.30582854 | AO4: -1.6868478 | AP4: -1.6184307 | AQ4: 1.9052497
A5: 124 | B5: 2023 | C5: Belgium | D5: 19.333333 | E5: 17.554461 | F5: 1.7788721 | G5: 1.3513205 | H5: 0.89074216 | I5: -0.80286731 | J5: 0.31567571 | K5: 0.30213082 | L5: 1.0218825 | M5: 0.52358695 | N5: -1.2557489 | O5: 0.07115932 | P5: -1.4421738 | Q5: 1.9052497 | R5: 1.3513205 | S5: 9.1137513 | T5: 0.022102599 | U5: 9.0916487 | V5: 0.89074216 | W5: 4.6286621 | X5: 0.094936804 | Y5: 4.5337253 | Z5: -0.80286731 | AA5: -0.31567571 | AB5: -0.3610543 | AC5: -0.24320733 | AD5: 1.3242276 | AE5: 0.45367637 | AF5: 0.89521734 | AG5: 1.0079023 | AH5: 1.2229596 | AI5: 1.227312 | AJ5: -0.53263083 | AK5: 1.633207 | AL5: 0.47018467 | AM5: 1.2557489 | AN5: 0.07115932 | AO5: -1.2784922 | AP5: -1.6058553 | AQ5: 1.9052497
A6: 128 | B6: 2023 | C6: Denmark | D6: 22 | E6: 23.012028 | F6: -1.0120279 | G6: 1.5163769 | H6: 0.64753099 | I6: -0.63700335 | J6: 0.3777779 | K6: 0.30213082 | L6: 1.7698904 | M6: 1.251327 | N6: 0.67396079 | O6: 1.4332184 | P6: 0.54832728 | Q6: 1.9052497 | R6: 1.5163769 | S6: 9.1137513 | T6: 0.022102599 | U6: 9.0916487 | V6: 0.64753099 | W6: 4.6286621 | X6: 0.094936804 | Y6: 4.5337253 | Z6: -0.63700335 | AA6: -0.3777779 | AB6: -0.3610543 | AC6: -0.24320733 | AD6: 1.7021874 | AE6: 0.98824427 | AF6: 1.9914874 | AG6: 1.7703085 | AH6: 1.8822413 | AI6: 2.2848736 | AJ6: 1.0395626 | AK6: 1.767436 | AL6: 0.94698235 | AM6: -0.67396079 | AN6: 1.4332184 | AO6: 0.58422422 | AP6: 0.51243033 | AQ6: 1.9052497
A7: 132 | B7: 2023 | C7: France | D7: 19.666667 | E7: 18.468881 | F7: 1.1977855 | G7: 1.1972556 | H7: 1.7036778 | I7: -0.8691867 | J7: 0.39506349 | K7: 0.30213082 | L7: 0.94904984 | M7: 0.57768211 | N7: -1.4328339 | O7: 0.088848734 | P7: -1.4326136 | Q7: 1.9052497 | R7: 1.1972556 | S7: 9.1137513 | T7: 0.022102599 | U7: 9.0916487 | V7: 1.7036778 | W7: 4.6286621 | X7: 0.094936804 | Y7: 4.5337253 | Z7: -0.8691867 | AA7: -0.39506349 | AB7: -0.3610543 | AC7: -0.24320733 | AD7: 1.1334158 | AE7: 0.38173612 | AF7: 1.0157567 | AG7: 0.99118441 | AH7: 1.0996007 | AI7: 1.0726053 | AJ7: -0.52583955 | AK7: 1.8141315 | AL7: 0.4447544 | AM7: 1.4328339 | AN7: 0.088848734 | AO7: -1.4555591 | AP7: -1.4096681 | AQ7: 1.9052497
A8: 134 | B8: 2023 | C8: Germany | D8: 22 | E8: 21.466101 | F8: 0.53389884 | G8: 1.349646 | H8: 1.9121006 | I8: -1.0209922 | J8: 0.27776571 | K8: 0.30213082 | L8: 1.2672908 | M8: 0.7547226 | N8: -0.1203657 | O8: 1.0582493 | P8: -1.5395165 | Q8: 1.9052497 | R8: 1.349646 | S8: 9.1137513 | T8: 0.022102599 | U8: 9.0916487 | V8: 1.9121006 | W8: 4.6286621 | X8: 0.094936804 | Y8: 4.5337253 | Z8: -1.0209922 | AA8: -0.27776571 | AB8: -0.3610543 | AC8: -0.24320733 | AD8: 1.4754885 | AE8: 0.67269141 | AF8: 1.0614513 | AG8: 1.3358428 | AH8: 1.4978565 | AI8: 1.5604146 | AJ8: 0.28828684 | AK8: 1.3404113 | AL8: 0.63546968 | AM8: 0.1203657 | AN8: 1.0582493 | AO8: -1.5706085 | AP8: -1.5084245 | AQ8: 1.9052497
A9: 136 | B9: 2023 | C9: Italy | D9: 13.666667 | E9: 16.496386 | F9: -2.8297189 | G9: 1.0922305 | H9: 1.5556689 | I9: -1.06928 | J9: 0.35066662 | K9: 0.30213082 | L9: 0.54432528 | M9: 0.29317024 | N9: -2.1277828 | O9: 0.42801222 | P9: -0.90886719 | Q9: 1.9052497 | R9: 1.0922305 | S9: 9.1137513 | T9: 0.022102599 | U9: 9.0916487 | V9: 1.5556689 | W9: 4.6286621 | X9: 0.094936804 | Y9: 4.5337253 | Z9: -1.06928 | AA9: -0.35066662 | AB9: -0.3610543 | AC9: -0.24320733 | AD9: 1.0898518 | AE9: 0.66830479 | AF9: 0.41802366 | AG9: 0.4125634 | AH9: 0.25050446 | AI9: 0.42670358 | AJ9: -0.57247634 | AK9: 1.4281097 | AL9: 0.0238773 | AM9: 2.1277828 | AN9: 0.42801222 | AO9: -0.96013718 | AP9: -0.85759721 | AQ9: 1.9052497
A10: 137 | B10: 2023 | C10: Luxembourg | D10: 22 | E10: 20.748664 | F10: 1.2513356 | G10: 2.0327943 | H10: -0.14397729 | I10: -0.53073516 | J10: 0.35246005 | K10: 0.30213082 | L10: 1.6981916 | M10: 0.91029767 | N10: 0.92703064 | O10: 0.70045247 | P10: -1.4981541 | Q10: 1.9052497 | R10: 2.0327943 | S10: 9.1137513 | T10: 0.022102599 | U10: 9.0916487 | V10: -0.14397729 | W10: 4.6286621 | X10: 0.094936804 | Y10: 4.5337253 | Z10: -0.53073516 | AA10: -0.35246005 | AB10: -0.3610543 | AC10: -0.24320733 | AD10: 1.6664665 | AE10: 1.2311991 | AF10: 1.8778576 | AG10: 1.8720047 | AH10: 1.7140783 | AI10: 1.8275432 | AJ10: 0.50984289 | AK10: 1.3350487 | AL10: 0.8860014 | AM10: -0.92703064 | AN10: 0.70045247 | AO10: -2.3386797 | AP10: -0.65762862 | AQ10: 1.9052497
A11: 138 | B11: 2023 | C11: Netherlands | D11: 22 | E11: 21.3671 | F11: 0.63290026 | G11: 1.4651433 | H11: 1.1862091 | I11: -0.64198058 | J11: 0.26219723 | K11: 0.30213082 | L11: 1.4952929 | M11: 0.7143679 | N11: 0.33696032 | O11: 1.2336564 | P11: -2.0233008 | Q11: 1.9052497 | R11: 1.4651433 | S11: 9.1137513 | T11: 0.022102599 | U11: 9.0916487 | V11: 1.1862091 | W11: 4.6286621 | X11: 0.094936804 | Y11: 4.5337253 | Z11: -0.64198058 | AA11: -0.26219723 | AB11: -0.3610543 | AC11: -0.24320733 | AD11: 1.5812798 | AE11: 0.75795176 | AF11: 1.5544735 | AG11: 1.7151645 | AH11: 1.5959556 | AI11: 1.7669324 | AJ11: 0.2893143 | AK11: 1.1735119 | AL11: 0.68027746 | AM11: -0.33696032 | AN11: 1.2336564 | AO11: -1.8277385 | AP11: -2.218863 | AQ11: 1.9052497
A12: 142 | B12: 2023 | C12: Norway | D12: 22 | E12: 23.808847 | F12: -1.8088475 | G12: 1.7040681 | H12: 0.73985482 | I12: -0.71733757 | J12: 0.2752282 | K12: 0.30213082 | L12: 1.6551482 | M12: 2.4488778 | N12: 0.3867186 | O12: 2.4058129 | P12: 0.40779863 | Q12: 1.9052497 | R12: 1.7040681 | S12: 9.1137513 | T12: 0.022102599 | U12: 9.0916487 | V12: 0.73985482 | W12: 4.6286621 | X12: 0.094936804 | Y12: 4.5337253 | Z12: -0.71733757 | AA12: -0.2752282 | AB12: -0.3610543 | AC12: -0.24320733 | AD12: 1.827689 | AE12: 1.0384835 | AF12: 1.7498419 | AG12: 1.4954666 | AH12: 1.801702 | AI12: 2.0177062 | AJ12: 3.452847 | AK12: 2.7287366 | AL12: 1.1650498 | AM12: -0.3867186 | AN12: 2.4058129 | AO12: 0.2799165 | AP12: 0.53568076 | AQ12: 1.9052497
A13: 144 | B13: 2023 | C13: Sweden | D13: 22 | E13: 21.795118 | F13: 0.20488235 | G13: 1.3507389 | H13: 0.83452117 | I13: -0.64918447 | J13: 0.23674582 | K13: 0.30213082 | L13: 1.5208156 | M13: 0.96748506 | N13: 0.72888659 | O13: 0.84562722 | P13: -0.20619644 | Q13: 1.9052497 | R13: 1.3507389 | S13: 9.1137513 | T13: 0.022102599 | U13: 9.0916487 | V13: 0.83452117 | W13: 4.6286621 | X13: 0.094936804 | Y13: 4.5337253 | Z13: -0.64918447 | AA13: -0.23674582 | AB13: -0.3610543 | AC13: -0.24320733 | AD13: 1.6019835 | AE13: 0.87764249 | AF13: 1.5274215 | AG13: 1.6323146 | AH13: 1.5546071 | AI13: 1.9309243 | AJ13: 0.61025858 | AK13: 1.5569762 | AL13: 0.73522044 | AM13: -0.72888659 | AN13: 0.84562722 | AO13: -0.1805197 | AP13: -0.23187319 | AQ13: 1.9052497
... A138: 968 | B138: 2023 | C138: Romania | D138: 13 | E138: 14.046677 | F138: -1.0466774 | G138: 0.51937183 | H138: 0.57306196 | I138: 0.095435133 | J138: -0.15817071 | K138: 0.30213082 | L138: 0.11779894 | M138: -0.17922926 | N138: 0.16412604 | O138: -0.64509386 | P138: 0.32681456 | Q138: -0.52486557 | R138: 0.51937183 | S138: 9.1137513 | T138: 0.022102599 | U138: 9.0916487 | V138: 0.57306196 | W138: 4.6286621 | X138: 0.094936804 | Y138: 4.5337253 | Z138: 0.095435133 | AA138: 0.15817071 | AB138: -0.3610543 | AC138: -0.24320733 | AD138: 0.40706558 | AE138: 0.41754898 | AF138: -0.37027317 | AG138: 0.043304124 | AH138: 0.30107876 | AI138: -0.091930606 | AJ138: -0.84650817 | AK138: 0.13490801 | AL138: 0.17391238 | AM138: -0.16412604 | AN138: -0.64509386 | AO138: 0.39544703 | AP138: 0.25818208 | AQ138: -0.52486557

Sheet 2023_new
A1: cc | B1: year | C1: name | D1: rating | E1: predicted_rating | F1: resid | G1: wealth_factor | H1: size_factor | I1: growth_factor | J1: inflation_factor | K1: default_factor | L1: governance_factor | M1: fiscalperf_factor | N1: govdebt_factor | O1: extperf_factor | P1: reservebuffer_factor | Q1: reservestatus_factor | R1: ngdp_pc | S1: median_ngdp_pc | T1: detrend_median_ngdp_pc | U1: trend_median_ngdp_pc | V1: ngdp | W1: median_ngdp | X1: detrend_median_ngdp | Y1: trend_median_ngdp | Z1: growth_avg | AA1: inf_avg | AB1: default_hist | AC1: default_decay | AD1: voice_acct | AE1: pol_stab | AF1: gov_eff | AG1: reg_qual | AH1: rule_law | AI1: cont_corrupt | AJ1: fb_avg | AK1: gov_rev_gdp | AL1: ir_rev | AM1: gov_debt_gdp | AN1: cab_avg | AO1: reserve_gdp | AP1: import_cover | AQ1: reserve_fx
A2: 111 | B2: 2023 | C2: United States | D2: 21.333333 | E2: 18.898517 | F2: 2.4348163 | G2: 1.6614344 | H2: 2.8554324 | I2: -0.52759164 | J2: 0.28282165 | K2: 0.30213082 | L2: 0.83764433 | M2: -0.51474114 | N2: -1.7165755 | O2: -0.16133751 | P2: -2.3964739 | Q2: 1.9052497 | R2: 1.6614344 | S2: 9.1137513 | T2: 0.022102599 | U2: 9.0916487 | V2: 2.8554324 | W2: 4.6286621 | X2: 0.094936804 | Y2: 4.5337253 | Z2: -0.52759164 | AA2: -0.28282165 | AB2: -0.3610543 | AC2: -0.24320733 | AD2: 0.79071613 | AE2: -0.27336381 | AF2: 1.1947255 | AG2: 1.3285642 | AH2: 0.90966121 | AI2: 1.0755628 | AJ2: -1.3046814 | AK2: 0.036896935 | AL2: -0.27643899 | AM2: 1.7165755 | AN2: -0.16133751 | AO2: -2.7125494 | AP2: -2.0803984 | AQ2: 1.9052497
A3: 112 | B3: 2023 | C3: United Kingdom | D3: 19.333333 | E3: 19.088919 | F3: 0.2444139 | G3: 1.2704945 | H3: 1.7540306 | I3: -0.92463478 | J3: 0.24867021 | K3: 0.30213082 | L3: 1.1126805 | M3: 0.097672065 | N3: -1.1753189 | O3: -0.23399601 | P3: -0.60163945 | Q3: 1.9052497 | R3: 1.2704945 | S3: 9.1137513 | T3: 0.022102599 | U3: 9.0916487 | V3: 1.7540306 | W3: 4.6286621 | X3: 0.094936804 | Y3: 4.5337253 | Z3: -0.92463478 | AA3: -0.24867021 | AB3: -0.3610543 | AC3: -0.24320733 | AD3: 1.2144678 | AE3: 0.40228747 | AF3: 0.94367181 | AG3: 1.5115984 | AH3: 1.2434715 | AI3: 1.3605859 | AJ3: -0.63404892 | AK3: 0.77305254 | AL3: 0.15401258 | AM3: 1.1753189 | AN3: -0.23399601 | AO3: -0.69989992 | AP3: -0.50337898 | AQ3: 1.9052497
A4: 122 | B4: 2023 | C4: Austria | D4: 21 | E4: 18.957766 | F4: 2.0422337 | G4: 1.369164 | H4: 0.77017188 | I4: -0.83111527 | J4: 0.24309914 | K4: 0.30213082 | L4: 1.3053375 | M4: 0.77258832 | N4: -0.56838463 | O4: 0.30582854 | P4: -1.6523367 | Q4: 1.9052497 | R4: 1.369164 | S4: 9.1137513 | T4: 0.022102599 | U4: 9.0916487 | V4: 0.77017188 | W4: 4.6286621 | X4: 0.094936804 | Y4: 4.5337253 | Z4: -0.83111527 | AA4: -0.24309914 | AB4: -0.3610543 | AC4: -0.24320733 | AD4: 1.4118524 | AE4: 0.80335897 | AF4: 1.4456689 | AG4: 1.3070708 | AH4: 1.661046 | AI4: 1.2030281 | AJ4: -0.0084995308 | AK4: 1.7049828 | AL4: 0.6212817 | AM4: 0.56838463 | AN4: 0.30582854 | AO4: -1.6869308 | AP4: -1.6177427 | AQ4: 1.9052497
A5: 124 | B5: 2023 | C5: Belgium | D5: 19.333333 | E5: 17.735677 | F5: 1.5976563 | G5: 1.3513205 | H5: 0.89074216 | I5: -0.80286731 | J5: 0.31567571 | K5: 0.30213082 | L5: 1.0734132 | M5: 0.52358664 | N5: -1.2557489 | O5: 0.07115932 | P5: -1.4134719 | Q5: 1.9052497 | R5: 1.3513205 | S5: 9.1137513 | T5: 0.022102599 | U5: 9.0916487 | V5: 0.89074216 | W5: 4.6286621 | X5: 0.094936804 | Y5: 4.5337253 | Z5: -0.80286731 | AA5: -0.31567571 | AB5: -0.3610543 | AC5: -0.24320733 | AD5: 1.5017598 | AE5: 0.1990069 | AF5: 0.97406611 | AG5: 1.1675274 | AH5: 1.2452427 | AI5: 1.3528766 | AJ5: -0.53263083 | AK5: 1.633207 | AL5: 0.47018374 | AM5: 1.2557489 | AN5: 0.07115932 | AO5: -1.2217635 | AP5: -1.6051802 | AQ5: 1.9052497
A6: 128 | B6: 2023 | C6: Denmark | D6: 22 | E6: 23.110471 | F6: -1.1104711 | G6: 1.5163769 | H6: 0.64753099 | I6: -0.63700335 | J6: 0.3777779 | K6: 0.30213082 | L6: 1.8503604 | M6: 1.2513268 | N6: 0.67396079 | O6: 1.4332184 | P6: 0.54908219 | Q6: 1.9052497 | R6: 1.5163769 | S6: 9.1137513 | T6: 0.022102599 | U6: 9.0916487 | V6: 0.64753099 | W6: 4.6286621 | X6: 0.094936804 | Y6: 4.5337253 | Z6: -0.63700335 | AA6: -0.3777779 | AB6: -0.3610543 | AC6: -0.24320733 | AD6: 1.944824 | AE6: 1.0427675 | AF6: 1.8745483 | AG6: 1.9746202 | AH6: 2.0454802 | AI6: 2.2199222 | AJ6: 1.0395626 | AK6: 1.767436 | AL6: 0.94698179 | AM6: -0.67396079 | AN6: 1.4332184 | AO6: 0.58504166 | AP6: 0.51312271 | AQ6: 1.9052497
A7: 132 | B7: 2023 | C7: France | D7: 19.666667 | E7: 18.36325 | F7: 1.3034169 | G7: 1.1972556 | H7: 1.7036778 | I7: -0.8691867 | J7: 0.39506349 | K7: 0.30213082 | L7: 0.90804671 | M7: 0.5776818 | N7: -1.4328339 | O7: 0.088848734 | P7: -1.4323325 | Q7: 1.9052497 | R7: 1.1972556 | S7: 9.1137513 | T7: 0.022102599 | U7: 9.0916487 | V7: 1.7036778 | W7: 4.6286621 | X7: 0.094936804 | Y7: 4.5337253 | Z7: -0.8691867 | AA7: -0.39506349 | AB7: -0.3610543 | AC7: -0.24320733 | AD7: 1.1297172 | AE7: -0.06354428 | AF7: 1.1870391 | AG7: 1.0996733 | AH7: 0.9462337 | AI7: 1.1491612 | AJ7: -0.52583955 | AK7: 1.8141315 | AL7: 0.44475345 | AM7: 1.4328339 | AN7: 0.088848734 | AO7: -1.4555682 | AP7: -1.4090969 | AQ7: 1.9052497
A8: 134 | B8: 2023 | C8: Germany | D8: 22 | E8: 21.65122 | F8: 0.34878016 | G8: 1.349646 | H8: 1.9121006 | I8: -1.0209922 | J8: 0.27776571 | K8: 0.30213082 | L8: 1.3550906 | M8: 0.75472234 | N8: -0.1203657 | O8: 1.0582493 | P8: -1.5392033 | Q8: 1.9052497 | R8: 1.349646 | S8: 9.1137513 | T8: 0.022102599 | U8: 9.0916487 | V8: 1.9121006 | W8: 4.6286621 | X8: 0.094936804 | Y8: 4.5337253 | Z8: -1.0209922 | AA8: -0.27776571 | AB8: -0.3610543 | AC8: -0.24320733 | AD8: 1.5850057 | AE8: 0.56796 | AF8: 1.4255611 | AG8: 1.3788734 | AH8: 1.5832603 | AI8: 1.5898828 | AJ8: 0.28828684 | AK8: 1.3404113 | AL8: 0.63546888 | AM8: 0.1203657 | AN8: 1.0582493 | AO8: -1.5706581 | AP8: -1.5077486 | AQ8: 1.9052497
A9: 136 | B9: 2023 | C9: Italy | D9: 13.666667 | E9: 16.772362 | F9: -3.105695 | G9: 1.0922305 | H9: 1.5556689 | I9: -1.06928 | J9: 0.35066662 | K9: 0.30213082 | L9: 0.6127735 | M9: 0.29316981 | N9: -2.1277828 | O9: 0.42801222 | P9: -0.90843542 | Q9: 1.9052497 | R9: 1.0922305 | S9: 9.1137513 | T9: 0.022102599 | U9: 9.0916487 | V9: 1.5556689 | W9: 4.6286621 | X9: 0.094936804 | Y9: 4.5337253 | Z9: -1.06928 | AA9: -0.35066662 | AB9: -0.3610543 | AC9: -0.24320733 | AD9: 1.0339907 | AE9: 0.52911491 | AF9: 0.61988726 | AG9: 0.47879794 | AH9: 0.57534207 | AI9: 0.43950816 | AJ9: -0.57247634 | AK9: 1.4281097 | AL9: 0.023876019 | AM9: 2.1277828 | AN9: 0.42801222 | AO9: -0.95993979 | AP9: -0.85693106 | AQ9: 1.9052497
A10: 137 | B10: 2023 | C10: Luxembourg | D10: 22 | E10: 20.774039 | F10: 1.2259609 | G10: 2.0327943 | H10: -0.14397729 | I10: -0.53073516 | J10: 0.35246005 | K10: 0.30213082 | L10: 1.7308632 | M10: 0.91029747 | N10: 0.92703064 | O10: 0.70045247 | P10: -1.4979933 | Q10: 1.9052497 | R10: 2.0327943 | S10: 9.1137513 | T10: 0.022102599 | U10: 9.0916487 | V10: -0.14397729 | W10: 4.6286621 | X10: 0.094936804 | Y10: 4.5337253 | Z10: -0.53073516 | AA10: -0.35246005 | AB10: -0.3610543 | AC10: -0.24320733 | AD10: 1.6681751 | AE10: 1.1812252 | AF10: 2.0903329 | AG10: 1.7988298 | AH10: 1.7375079 | AI10: 1.9091085 | AJ10: 0.50984289 | AK10: 1.3350487 | AL10: 0.8860008 | AM10: -0.92703064 | AN10: 0.70045247 | AO10: -2.3390407 | AP10: -0.65694577 | AQ10: 1.9052497
A11: 138 | B11: 2023 | C11: Netherlands | D11: 22 | E11: 21.407861 | F11: 0.59213909 | G11: 1.4651433 | H11: 1.1862091 | I11: -0.64198058 | J11: 0.26219723 | K11: 0.30213082 | L11: 1.5334098 | M11: 0.71436765 | N11: 0.33696032 | O11: 1.2336564 | P11: -2.0231127 | Q11: 1.9052497 | R11: 1.4651433 | S11: 9.1137513 | T11: 0.022102599 | U11: 9.0916487 | V11: 1.1862091 | W11: 4.6286621 | X11: 0.094936804 | Y11: 4.5337253 | Z11: -0.64198058 | AA11: -0.26219723 | AB11: -0.3610543 | AC11: -0.24320733 | AD11: 1.7035877 | AE11: 0.69120629 | AF11: 1.6414676 | AG11: 1.6608843 | AH11: 1.7254626 | AI11: 1.7778503 | AJ11: 0.2893143 | AK11: 1.1735119 | AL11: 0.68027669 | AM11: -0.33696032 | AN11: 1.2336564 | AO11: -1.8279032 | AP11: -2.2183221 | AQ11: 1.9052497
A12: 142 | B12: 2023 | C12: Norway | D12: 22 | E12: 23.775678 | F12: -1.7756778 | G12: 1.7040681 | H12: 0.73985482 | I12: -0.71733757 | J12: 0.2752282 | K12: 0.30213082 | L12: 1.7129826 | M12: 2.4488777 | N12: 0.3867186 | O12: 2.4058129 | P12: 0.39492916 | Q12: 1.9052497 | R12: 1.7040681 | S12: 9.1137513 | T12: 0.022102599 | U12: 9.0916487 | V12: 0.73985482 | W12: 4.6286621 | X12: 0.094936804 | Y12: 4.5337253 | Z12: -0.71733757 | AA12: -0.2752282 | AB12: -0.3610543 | AC12: -0.24320733 | AD12: 1.9577335 | AE12: 1.0856028 | AF12: 1.6823055 | AG12: 1.5649116 | AH12: 2.0148819 | AI12: 1.9724602 | AJ12: 3.452847 | AK12: 2.7287366 | AL12: 1.1650494 | AM12: -0.3867186 | AN12: 2.4058129 | AO12: 0.25557259 | AP12: 0.53428572 | AQ12: 1.9052497
A13: 144 | B13: 2023 | C13: Sweden | D13: 22 | E13: 21.816798 | F13: 0.18320229 | G13: 1.3507389 | H13: 0.83452117 | I13: -0.64918447 | J13: 0.23674582 | K13: 0.30213082 | L13: 1.5655746 | M13: 0.96748482 | N13: 0.72888659 | O13: 0.84562722 | P13: -0.20557425 | Q13: 1.9052497 | R13: 1.3507389 | S13: 9.1137513 | T13: 0.022102599 | U13: 9.0916487 | V13: 0.83452117 | W13: 4.6286621 | X13: 0.094936804 | Y13: 4.5337253 | Z13: -0.64918447 | AA13: -0.23674582 | AB13: -0.3610543 | AC13: -0.24320733 | AD13: 1.7365364 | AE13: 0.89621125 | AF13: 1.5753491 | AG13: 1.6079226 | AH13: 1.7009365 | AI13: 1.8764918 | AJ13: 0.61025858 | AK13: 1.5569762 | AL13: 0.73521972 | AM13: -0.72888659 | AN13: 0.84562722 | AO13: -0.17996417 | AP13: -0.23118432 | AQ13: 1.9052497
... A138: 968 | B138: 2023 | C138: Romania | D138: 13 | E138: 14.178187 | F138: -1.1781868 | G138: 0.51937183 | H138: 0.57306196 | I138: 0.095435133 | J138: -0.15817071 | K138: 0.30213082 | L138: 0.17150644 | M138: -0.17922965 | N138: 0.16412604 | O138: -0.64509386 | P138: 0.33028412 | Q138: -0.52486557 | R138: 0.51937183 | S138: 9.1137513 | T138: 0.022102599 | U138: 9.0916487 | V138: 0.57306196 | W138: 4.6286621 | X138: 0.094936804 | Y138: 4.5337253 | Z138: 0.095435133 | AA138: 0.15817071 | AB138: -0.3610543 | AC138: -0.24320733 | AD138: 0.39138139 | AE138: 0.55874119 | AF138: -0.20100825 | AG138: 0.073086481 | AH138: 0.31801952 | AI138: -0.11118172 | AJ138: -0.84650817 | AK138: 0.13490801 | AL138: 0.17391122 | AM138: -0.16412604 | AN138: -0.64509386 | AO138: 0.40169585 | AP138: 0.25887239 | AQ138: -0.52486557

Sheet 2024_new
A1: cc | B1: year | C1: name | D1: rating | E1: predicted_rating | F1: resid | G1: wealth_factor | H1: size_factor | I1: growth_factor | J1: inflation_factor | K1: default_factor | L1: governance_factor | M1: fiscalperf_factor | N1: govdebt_factor | O1: extperf_factor | P1: reservebuffer_factor | Q1: reservestatus_factor | R1: ngdp_pc | S1: median_ngdp_pc | T1: detrend_median_ngdp_pc | U1: trend_median_ngdp_pc | V1: ngdp | W1: median_ngdp | X1: detrend_median_ngdp | Y1: trend_median_ngdp | Z1: growth_avg | AA1: inf_avg | AB1: default_hist | AC1: default_decay | AD1: voice_acct | AE1: pol_stab | AF1: gov_eff | AG1: reg_qual | AH1: rule_law | AI1: cont_corrupt | AJ1: fb_avg | AK1: gov_rev_gdp | AL1: ir_rev | AM1: gov_debt_gdp | AN1: cab_avg | AO1: reserve_gdp | AP1: import_cover | AQ1: reserve_fx
A2: 111 | B2: 2024 | C2: United States | D2: 21.333333 | E2: 18.820344 | F2: 2.5129891 | G2: 1.690399 | H2: 2.867654 | I2: -0.39573874 | J2: 0.28553087 | K2: 0.30213082 | L2: 0.82855756 | M2: -0.53474057 | N2: -1.7856425 | O2: -0.18443203 | P2: -2.4592715 | Q2: 1.9052497 | R2: 1.690399 | S2: 9.2051622 | T2: 0.10860756 | U2: 9.0965546 | V2: 2.867654 | W2: 4.672296 | X2: 0.10991564 | Y2: 4.5623803 | Z2: -0.39573874 | AA2: -0.28553087 | AB2: -0.3610543 | AC2: -0.24320733 | AD2: 0.81618166 | AE2: -0.15540861 | AF2: 1.1963812 | AG2: 1.2381495 | AH2: 0.9108459 | AI2: 0.96519575 | AJ2: -1.2719279 | AK2: 0.039784467 | AL2: -0.37207832 | AM2: 1.7856425 | AN2: -0.18443203 | AO2: -2.7888722 | AP2: -2.1296708 | AQ2: 1.9052497
A3: 112 | B3: 2024 | C3: United Kingdom | D3: 19.333333 | E3: 19.152893 | F3: 0.18044066 | G3: 1.3155084 | H3: 1.7797921 | I3: -0.87804966 | J3: 0.27187029 | K3: 0.30213082 | L3: 1.0991731 | M3: 0.1027623 | N3: -1.1995729 | O3: -0.10773911 | P3: -0.6504941 | Q3: 1.9052497 | R3: 1.3155084 | S3: 9.2051622 | T3: 0.10860756 | U3: 9.0965546 | V3: 1.7797921 | W3: 4.672296 | X3: 0.10991564 | Y3: 4.5623803 | Z3: -0.87804966 | AA3: -0.27187029 | AB3: -0.3610543 | AC3: -0.24320733 | AD3: 1.2675474 | AE3: 0.26915693 | AF3: 0.99717107 | AG3: 1.4217018 | AH3: 1.2429962 | AI3: 1.3964651 | AJ3: -0.68675024 | AK3: 0.7331221 | AL3: 0.26191503 | AM3: 1.1995729 | AN3: -0.10773911 | AO3: -0.78352578 | AP3: -0.51746241 | AQ3: 1.9052497
A4: 122 | B4: 2024 | C4: Austria | D4: 21 | E4: 18.672103 | F4: 2.3278965 | G4: 1.3787467 | H4: 0.7674339 | I4: -1.056313 | J4: 0.24752547 | K4: 0.30213082 | L4: 1.2334629 | M4: 0.71966684 | N4: -0.63175627 | O4: 0.4777443 | P4: -1.8007155 | Q4: 1.9052497 | R4: 1.3787467 | S4: 9.2051622 | T4: 0.10860756 | U4: 9.0965546 | V4: 0.7674339 | W4: 4.672296 | X4: 0.10991564 | Y4: 4.5623803 | Z4: -1.056313 | AA4: -0.24752547 | AB4: -0.3610543 | AC4: -0.24320733 | AD4: 1.3819502 | AE4: 0.5506054 | AF4: 1.3722223 | AG4: 1.2364995 | AH4: 1.6826228 | AI4: 1.1768774 | AJ4: -0.22692307 | AK4: 1.8134715 | AL4: 0.57245211 | AM4: 0.63175627 | AN4: 0.4777443 | AO4: -1.7596579 | AP4: -1.841773 | AQ4: 1.9052497
A5: 124 | B5: 2024 | C5: Belgium | D5: 19.333333 | E5: 17.644544 | F5: 1.6887896 | G5: 1.3654938 | H5: 0.89135513 | I5: -0.77684601 | J5: 0.3317784 | K5: 0.30213082 | L5: 1.0532288 | M5: 0.49367798 | N5: -1.2962001 | O5: 0.2234719 | P5: -1.615386 | Q5: 1.9052497 | R5: 1.3654938 | S5: 9.2051622 | T5: 0.10860756 | U5: 9.0965546 | V5: 0.89135513 | W5: 4.672296 | X5: 0.10991564 | Y5: 4.5623803 | Z5: -0.77684601 | AA5: -0.3317784 | AB5: -0.3610543 | AC5: -0.24320733 | AD5: 1.482072 | AE5: 0.10519436 | AF5: 1.0083566 | AG5: 1.1121873 | AH5: 1.2568859 | AI5: 1.3546767 | AJ5: -0.65755526 | AK5: 1.6964852 | AL5: 0.44210402 | AM5: 1.2962001 | AN5: 0.2234719 | AO5: -1.5089518 | AP5: -1.7218201 | AQ5: 1.9052497
